supervisor: couldn't chdir to /hoeme/kirill/spb-beer-bot: ENOENT
supervisor: child process was not spawned
supervisor: couldn't chdir to /hoeme/kirill/spb-beer-bot: ENOENT
supervisor: child process was not spawned
supervisor: couldn't chdir to /hoeme/kirill/spb-beer-bot: ENOENT
supervisor: child process was not spawned
supervisor: couldn't chdir to /hoeme/kirill/spb-beer-bot: ENOENT
supervisor: child process was not spawned
supervisor: couldn't chdir to /hoeme/kirill/spb-beer-bot: ENOENT
supervisor: child process was not spawned
supervisor: couldn't chdir to /hoeme/kirill/spb-beer-bot: ENOENT
supervisor: child process was not spawned
supervisor: couldn't chdir to /hoeme/kirill/spb-beer-bot: ENOENT
supervisor: child process was not spawned
supervisor: couldn't chdir to /hoeme/kirill/spb-beer-bot: ENOENT
supervisor: child process was not spawned
supervisor: couldn't chdir to /hoeme/kirill/spb-beer-bot: ENOENT
supervisor: child process was not spawned
supervisor: couldn't chdir to /hoeme/kirill/spb-beer-bot: ENOENT
supervisor: child process was not spawned
supervisor: couldn't chdir to /hoeme/kirill/spb-beer-bot: ENOENT
supervisor: child process was not spawned
supervisor: couldn't chdir to /hoeme/kirill/spb-beer-bot: ENOENT
supervisor: child process was not spawned
supervisor: couldn't chdir to /hoeme/kirill/spb-beer-bot: ENOENT
supervisor: child process was not spawned
supervisor: couldn't chdir to /hoeme/kirill/spb-beer-bot: ENOENT
supervisor: child process was not spawned
supervisor: couldn't chdir to /hoeme/kirill/spb-beer-bot: ENOENT
supervisor: child process was not spawned
supervisor: couldn't chdir to /hoeme/kirill/spb-beer-bot: ENOENT
supervisor: child process was not spawned
supervisor: couldn't chdir to /hoeme/kirill/spb-beer-bot: ENOENT
supervisor: child process was not spawned
supervisor: couldn't chdir to /hoeme/kirill/spb-beer-bot: ENOENT
supervisor: child process was not spawned
supervisor: couldn't chdir to /hoeme/kirill/spb-beer-bot: ENOENT
supervisor: child process was not spawned
supervisor: couldn't chdir to /hoeme/kirill/spb-beer-bot: ENOENT
supervisor: child process was not spawned
supervisor: couldn't chdir to /hoeme/kirill/spb-beer-bot: ENOENT
supervisor: child process was not spawned
supervisor: couldn't chdir to /hoeme/kirill/spb-beer-bot: ENOENT
supervisor: child process was not spawned
supervisor: couldn't chdir to /hoeme/kirill/spb-beer-bot: ENOENT
supervisor: child process was not spawned
supervisor: couldn't chdir to /hoeme/kirill/spb-beer-bot: ENOENT
supervisor: child process was not spawned
supervisor: couldn't chdir to /hoeme/kirill/spb-beer-bot: ENOENT
supervisor: child process was not spawned
supervisor: couldn't chdir to /hoeme/kirill/spb-beer-bot: ENOENT
supervisor: child process was not spawned
supervisor: couldn't chdir to /hoeme/kirill/spb-beer-bot: ENOENT
supervisor: child process was not spawned
supervisor: couldn't chdir to /hoeme/kirill/spb-beer-bot: ENOENT
supervisor: child process was not spawned
supervisor: couldn't chdir to /hoeme/kirill/spb-beer-bot: ENOENT
supervisor: child process was not spawned
supervisor: couldn't chdir to /hoeme/kirill/spb-beer-bot: ENOENT
supervisor: child process was not spawned
supervisor: couldn't chdir to /hoeme/kirill/spb-beer-bot: ENOENT
supervisor: child process was not spawned
supervisor: couldn't chdir to /hoeme/kirill/spb-beer-bot: ENOENT
supervisor: child process was not spawned
supervisor: couldn't chdir to /hoeme/kirill/spb-beer-bot: ENOENT
supervisor: child process was not spawned
supervisor: couldn't chdir to /hoeme/kirill/spb-beer-bot: ENOENT
supervisor: child process was not spawned
supervisor: couldn't chdir to /hoeme/kirill/spb-beer-bot: ENOENT
supervisor: child process was not spawned
supervisor: couldn't chdir to /hoeme/kirill/spb-beer-bot: ENOENT
supervisor: child process was not spawned
supervisor: couldn't chdir to /hoeme/kirill/spb-beer-bot: ENOENT
supervisor: child process was not spawned
supervisor: couldn't chdir to /hoeme/kirill/spb-beer-bot: ENOENT
supervisor: child process was not spawned
supervisor: couldn't chdir to /hoeme/kirill/spb-beer-bot: ENOENT
supervisor: child process was not spawned
supervisor: couldn't chdir to /hoeme/kirill/spb-beer-bot: ENOENT
supervisor: child process was not spawned
supervisor: couldn't chdir to /hoeme/kirill/spb-beer-bot: ENOENT
supervisor: child process was not spawned
supervisor: couldn't chdir to /hoeme/kirill/spb-beer-bot: ENOENT
supervisor: child process was not spawned
supervisor: couldn't chdir to /hoeme/kirill/spb-beer-bot: ENOENT
supervisor: child process was not spawned
supervisor: couldn't chdir to /hoeme/kirill/spb-beer-bot: ENOENT
supervisor: child process was not spawned
supervisor: couldn't chdir to /hoeme/kirill/spb-beer-bot: ENOENT
supervisor: child process was not spawned
supervisor: couldn't chdir to /hoeme/kirill/spb-beer-bot: ENOENT
supervisor: child process was not spawned
supervisor: couldn't chdir to /hoeme/kirill/spb-beer-bot: ENOENT
supervisor: child process was not spawned
supervisor: couldn't chdir to /hoeme/kirill/spb-beer-bot: ENOENT
supervisor: child process was not spawned
supervisor: couldn't chdir to /hoeme/kirill/spb-beer-bot: ENOENT
supervisor: child process was not spawned
supervisor: couldn't chdir to /hoeme/kirill/spb-beer-bot: ENOENT
supervisor: child process was not spawned
supervisor: couldn't chdir to /hoeme/kirill/spb-beer-bot: ENOENT
supervisor: child process was not spawned
supervisor: couldn't chdir to /hoeme/kirill/spb-beer-bot: ENOENT
supervisor: child process was not spawned
supervisor: couldn't chdir to /hoeme/kirill/spb-beer-bot: ENOENT
supervisor: child process was not spawned
supervisor: couldn't chdir to /hoeme/kirill/spb-beer-bot: ENOENT
supervisor: child process was not spawned
supervisor: couldn't chdir to /hoeme/kirill/spb-beer-bot: ENOENT
supervisor: child process was not spawned
supervisor: couldn't chdir to /hoeme/kirill/spb-beer-bot: ENOENT
supervisor: child process was not spawned
supervisor: couldn't chdir to /hoeme/kirill/spb-beer-bot: ENOENT
supervisor: child process was not spawned
supervisor: couldn't chdir to /hoeme/kirill/spb-beer-bot: ENOENT
supervisor: child process was not spawned
supervisor: couldn't chdir to /hoeme/kirill/spb-beer-bot: ENOENT
supervisor: child process was not spawned
supervisor: couldn't chdir to /hoeme/kirill/spb-beer-bot: ENOENT
supervisor: child process was not spawned
supervisor: couldn't chdir to /hoeme/kirill/spb-beer-bot: ENOENT
supervisor: child process was not spawned
supervisor: couldn't chdir to /hoeme/kirill/spb-beer-bot: ENOENT
supervisor: child process was not spawned
supervisor: couldn't chdir to /hoeme/kirill/spb-beer-bot: ENOENT
supervisor: child process was not spawned
supervisor: couldn't chdir to /hoeme/kirill/spb-beer-bot: ENOENT
supervisor: child process was not spawned
supervisor: couldn't chdir to /hoeme/kirill/spb-beer-bot: ENOENT
supervisor: child process was not spawned
supervisor: couldn't chdir to /hoeme/kirill/spb-beer-bot: ENOENT
supervisor: child process was not spawned
supervisor: couldn't chdir to /hoeme/kirill/spb-beer-bot: ENOENT
supervisor: child process was not spawned
supervisor: couldn't chdir to /hoeme/kirill/spb-beer-bot: ENOENT
supervisor: child process was not spawned
supervisor: couldn't chdir to /hoeme/kirill/spb-beer-bot: ENOENT
supervisor: child process was not spawned
supervisor: couldn't chdir to /hoeme/kirill/spb-beer-bot: ENOENT
supervisor: child process was not spawned
supervisor: couldn't chdir to /hoeme/kirill/spb-beer-bot: ENOENT
supervisor: child process was not spawned
supervisor: couldn't chdir to /hoeme/kirill/spb-beer-bot: ENOENT
supervisor: child process was not spawned
supervisor: couldn't chdir to /hoeme/kirill/spb-beer-bot: ENOENT
supervisor: child process was not spawned
supervisor: couldn't chdir to /hoeme/kirill/spb-beer-bot: ENOENT
supervisor: child process was not spawned
supervisor: couldn't chdir to /hoeme/kirill/spb-beer-bot: ENOENT
supervisor: child process was not spawned
supervisor: couldn't chdir to /hoeme/kirill/spb-beer-bot: ENOENT
supervisor: child process was not spawned
supervisor: couldn't chdir to /hoeme/kirill/spb-beer-bot: ENOENT
supervisor: child process was not spawned
supervisor: couldn't chdir to /hoeme/kirill/spb-beer-bot: ENOENT
supervisor: child process was not spawned
supervisor: couldn't chdir to /hoeme/kirill/spb-beer-bot: ENOENT
supervisor: child process was not spawned
supervisor: couldn't chdir to /hoeme/kirill/spb-beer-bot: ENOENT
supervisor: child process was not spawned
supervisor: couldn't chdir to /hoeme/kirill/spb-beer-bot: ENOENT
supervisor: child process was not spawned
supervisor: couldn't chdir to /hoeme/kirill/spb-beer-bot: ENOENT
supervisor: child process was not spawned
supervisor: couldn't chdir to /hoeme/kirill/spb-beer-bot: ENOENT
supervisor: child process was not spawned
supervisor: couldn't chdir to /hoeme/kirill/spb-beer-bot: ENOENT
supervisor: child process was not spawned
supervisor: couldn't chdir to /hoeme/kirill/spb-beer-bot: ENOENT
supervisor: child process was not spawned
supervisor: couldn't chdir to /hoeme/kirill/spb-beer-bot: ENOENT
supervisor: child process was not spawned
supervisor: couldn't chdir to /hoeme/kirill/spb-beer-bot: ENOENT
supervisor: child process was not spawned
supervisor: couldn't chdir to /hoeme/kirill/spb-beer-bot: ENOENT
supervisor: child process was not spawned
supervisor: couldn't chdir to /hoeme/kirill/spb-beer-bot: ENOENT
supervisor: child process was not spawned
supervisor: couldn't chdir to /hoeme/kirill/spb-beer-bot: ENOENT
supervisor: child process was not spawned
supervisor: couldn't chdir to /hoeme/kirill/spb-beer-bot: ENOENT
supervisor: child process was not spawned
supervisor: couldn't chdir to /hoeme/kirill/spb-beer-bot: ENOENT
supervisor: child process was not spawned
supervisor: couldn't chdir to /hoeme/kirill/spb-beer-bot: ENOENT
supervisor: child process was not spawned
supervisor: couldn't chdir to /hoeme/kirill/spb-beer-bot: ENOENT
supervisor: child process was not spawned
supervisor: couldn't chdir to /hoeme/kirill/spb-beer-bot: ENOENT
supervisor: child process was not spawned
supervisor: couldn't chdir to /hoeme/kirill/spb-beer-bot: ENOENT
supervisor: child process was not spawned
supervisor: couldn't chdir to /hoeme/kirill/spb-beer-bot: ENOENT
supervisor: child process was not spawned
supervisor: couldn't chdir to /hoeme/kirill/spb-beer-bot: ENOENT
supervisor: child process was not spawned
supervisor: couldn't chdir to /hoeme/kirill/spb-beer-bot: ENOENT
supervisor: child process was not spawned
supervisor: couldn't chdir to /hoeme/kirill/spb-beer-bot: ENOENT
supervisor: child process was not spawned
supervisor: couldn't chdir to /hoeme/kirill/spb-beer-bot: ENOENT
supervisor: child process was not spawned
supervisor: couldn't chdir to /hoeme/kirill/spb-beer-bot: ENOENT
supervisor: child process was not spawned
supervisor: couldn't chdir to /hoeme/kirill/spb-beer-bot: ENOENT
supervisor: child process was not spawned
supervisor: couldn't chdir to /hoeme/kirill/spb-beer-bot: ENOENT
supervisor: child process was not spawned
supervisor: couldn't chdir to /hoeme/kirill/spb-beer-bot: ENOENT
supervisor: child process was not spawned
supervisor: couldn't chdir to /hoeme/kirill/spb-beer-bot: ENOENT
supervisor: child process was not spawned
supervisor: couldn't chdir to /hoeme/kirill/spb-beer-bot: ENOENT
supervisor: child process was not spawned
supervisor: couldn't chdir to /hoeme/kirill/spb-beer-bot: ENOENT
supervisor: child process was not spawned
supervisor: couldn't chdir to /hoeme/kirill/spb-beer-bot: ENOENT
supervisor: child process was not spawned
supervisor: couldn't chdir to /hoeme/kirill/spb-beer-bot: ENOENT
supervisor: child process was not spawned
supervisor: couldn't chdir to /hoeme/kirill/spb-beer-bot: ENOENT
supervisor: child process was not spawned
supervisor: couldn't chdir to /hoeme/kirill/spb-beer-bot: ENOENT
supervisor: child process was not spawned
supervisor: couldn't chdir to /hoeme/kirill/spb-beer-bot: ENOENT
supervisor: child process was not spawned
supervisor: couldn't chdir to /hoeme/kirill/spb-beer-bot: ENOENT
supervisor: child process was not spawned
supervisor: couldn't chdir to /hoeme/kirill/spb-beer-bot: ENOENT
supervisor: child process was not spawned
supervisor: couldn't chdir to /hoeme/kirill/spb-beer-bot: ENOENT
supervisor: child process was not spawned
supervisor: couldn't chdir to /hoeme/kirill/spb-beer-bot: ENOENT
supervisor: child process was not spawned
supervisor: couldn't chdir to /hoeme/kirill/spb-beer-bot: ENOENT
supervisor: child process was not spawned
supervisor: couldn't chdir to /hoeme/kirill/spb-beer-bot: ENOENT
supervisor: child process was not spawned
supervisor: couldn't chdir to /hoeme/kirill/spb-beer-bot: ENOENT
supervisor: child process was not spawned
supervisor: couldn't chdir to /hoeme/kirill/spb-beer-bot: ENOENT
supervisor: child process was not spawned
supervisor: couldn't chdir to /hoeme/kirill/spb-beer-bot: ENOENT
supervisor: child process was not spawned
supervisor: couldn't chdir to /hoeme/kirill/spb-beer-bot: ENOENT
supervisor: child process was not spawned
supervisor: couldn't chdir to /hoeme/kirill/spb-beer-bot: ENOENT
supervisor: child process was not spawned
supervisor: couldn't chdir to /hoeme/kirill/spb-beer-bot: ENOENT
supervisor: child process was not spawned
supervisor: couldn't chdir to /hoeme/kirill/spb-beer-bot: ENOENT
supervisor: child process was not spawned
supervisor: couldn't chdir to /hoeme/kirill/spb-beer-bot: ENOENT
supervisor: child process was not spawned
Task exception was never retrieved
future: <Task finished name='Task-372' coro=<Dispatcher._process_polling_updates() done, defined at /usr/local/lib/python3.8/dist-packages/aiogram/dispatcher/dispatcher.py:407> exception=KeyError('message_pub')>
Traceback (most recent call last):
  File "/usr/local/lib/python3.8/dist-packages/aiogram/dispatcher/dispatcher.py", line 415, in _process_polling_updates
    for responses in itertools.chain.from_iterable(await self.process_updates(updates, fast)):
  File "/usr/local/lib/python3.8/dist-packages/aiogram/dispatcher/dispatcher.py", line 235, in process_updates
    return await asyncio.gather(*tasks)
  File "/usr/local/lib/python3.8/dist-packages/aiogram/dispatcher/handler.py", line 116, in notify
    response = await handler_obj.handler(*args, **partial_data)
  File "/usr/local/lib/python3.8/dist-packages/aiogram/dispatcher/dispatcher.py", line 256, in process_update
    return await self.message_handlers.notify(update.message)
  File "/usr/local/lib/python3.8/dist-packages/aiogram/dispatcher/handler.py", line 116, in notify
    response = await handler_obj.handler(*args, **partial_data)
  File "/home/kirill/spb-beer-bot/tgbot/handlers/start.py", line 61, in take_user_location
    await send_next_three_pubs(message.from_user.id, state)
  File "/home/kirill/spb-beer-bot/tgbot/handlers/start.py", line 83, in send_next_three_pubs
    data['message_pub'][sent_message.message_id] = pub
  File "/usr/local/lib/python3.8/dist-packages/aiogram/dispatcher/storage.py", line 439, in __getitem__
    return self._data[item]
KeyError: 'message_pub'
Task exception was never retrieved
future: <Task finished name='Task-390' coro=<Dispatcher._process_polling_updates() done, defined at /usr/local/lib/python3.8/dist-packages/aiogram/dispatcher/dispatcher.py:407> exception=KeyError('message_pub')>
Traceback (most recent call last):
  File "/usr/local/lib/python3.8/dist-packages/aiogram/dispatcher/dispatcher.py", line 415, in _process_polling_updates
    for responses in itertools.chain.from_iterable(await self.process_updates(updates, fast)):
  File "/usr/local/lib/python3.8/dist-packages/aiogram/dispatcher/dispatcher.py", line 235, in process_updates
    return await asyncio.gather(*tasks)
  File "/usr/local/lib/python3.8/dist-packages/aiogram/dispatcher/handler.py", line 116, in notify
    response = await handler_obj.handler(*args, **partial_data)
  File "/usr/local/lib/python3.8/dist-packages/aiogram/dispatcher/dispatcher.py", line 256, in process_update
    return await self.message_handlers.notify(update.message)
  File "/usr/local/lib/python3.8/dist-packages/aiogram/dispatcher/handler.py", line 116, in notify
    response = await handler_obj.handler(*args, **partial_data)
  File "/home/kirill/spb-beer-bot/tgbot/handlers/start.py", line 61, in take_user_location
    await send_next_three_pubs(message.from_user.id, state)
  File "/home/kirill/spb-beer-bot/tgbot/handlers/start.py", line 83, in send_next_three_pubs
    data['message_pub'][sent_message.message_id] = pub
  File "/usr/local/lib/python3.8/dist-packages/aiogram/dispatcher/storage.py", line 439, in __getitem__
    return self._data[item]
KeyError: 'message_pub'
Task exception was never retrieved
future: <Task finished name='Task-407' coro=<Dispatcher._process_polling_updates() done, defined at /usr/local/lib/python3.8/dist-packages/aiogram/dispatcher/dispatcher.py:407> exception=KeyError('message_pub')>
Traceback (most recent call last):
  File "/usr/local/lib/python3.8/dist-packages/aiogram/dispatcher/dispatcher.py", line 415, in _process_polling_updates
    for responses in itertools.chain.from_iterable(await self.process_updates(updates, fast)):
  File "/usr/local/lib/python3.8/dist-packages/aiogram/dispatcher/dispatcher.py", line 235, in process_updates
    return await asyncio.gather(*tasks)
  File "/usr/local/lib/python3.8/dist-packages/aiogram/dispatcher/handler.py", line 116, in notify
    response = await handler_obj.handler(*args, **partial_data)
  File "/usr/local/lib/python3.8/dist-packages/aiogram/dispatcher/dispatcher.py", line 256, in process_update
    return await self.message_handlers.notify(update.message)
  File "/usr/local/lib/python3.8/dist-packages/aiogram/dispatcher/handler.py", line 116, in notify
    response = await handler_obj.handler(*args, **partial_data)
  File "/home/kirill/spb-beer-bot/tgbot/handlers/start.py", line 61, in take_user_location
    await send_next_three_pubs(message.from_user.id, state)
  File "/home/kirill/spb-beer-bot/tgbot/handlers/start.py", line 83, in send_next_three_pubs
    data['message_pub'][sent_message.message_id] = pub
  File "/usr/local/lib/python3.8/dist-packages/aiogram/dispatcher/storage.py", line 439, in __getitem__
    return self._data[item]
KeyError: 'message_pub'
Task exception was never retrieved
future: <Task finished name='Task-423' coro=<Dispatcher._process_polling_updates() done, defined at /usr/local/lib/python3.8/dist-packages/aiogram/dispatcher/dispatcher.py:407> exception=KeyError('message_pub')>
Traceback (most recent call last):
  File "/usr/local/lib/python3.8/dist-packages/aiogram/dispatcher/dispatcher.py", line 415, in _process_polling_updates
    for responses in itertools.chain.from_iterable(await self.process_updates(updates, fast)):
  File "/usr/local/lib/python3.8/dist-packages/aiogram/dispatcher/dispatcher.py", line 235, in process_updates
    return await asyncio.gather(*tasks)
  File "/usr/local/lib/python3.8/dist-packages/aiogram/dispatcher/handler.py", line 116, in notify
    response = await handler_obj.handler(*args, **partial_data)
  File "/usr/local/lib/python3.8/dist-packages/aiogram/dispatcher/dispatcher.py", line 256, in process_update
    return await self.message_handlers.notify(update.message)
  File "/usr/local/lib/python3.8/dist-packages/aiogram/dispatcher/handler.py", line 116, in notify
    response = await handler_obj.handler(*args, **partial_data)
  File "/home/kirill/spb-beer-bot/tgbot/handlers/start.py", line 61, in take_user_location
    await send_next_three_pubs(message.from_user.id, state)
  File "/home/kirill/spb-beer-bot/tgbot/handlers/start.py", line 83, in send_next_three_pubs
    data['message_pub'][sent_message.message_id] = pub
  File "/usr/local/lib/python3.8/dist-packages/aiogram/dispatcher/storage.py", line 439, in __getitem__
    return self._data[item]
KeyError: 'message_pub'
Task exception was never retrieved
future: <Task finished name='Task-454' coro=<Dispatcher._process_polling_updates() done, defined at /usr/local/lib/python3.8/dist-packages/aiogram/dispatcher/dispatcher.py:407> exception=KeyError('message_pub')>
Traceback (most recent call last):
  File "/usr/local/lib/python3.8/dist-packages/aiogram/dispatcher/dispatcher.py", line 415, in _process_polling_updates
    for responses in itertools.chain.from_iterable(await self.process_updates(updates, fast)):
  File "/usr/local/lib/python3.8/dist-packages/aiogram/dispatcher/dispatcher.py", line 235, in process_updates
    return await asyncio.gather(*tasks)
  File "/usr/local/lib/python3.8/dist-packages/aiogram/dispatcher/handler.py", line 116, in notify
    response = await handler_obj.handler(*args, **partial_data)
  File "/usr/local/lib/python3.8/dist-packages/aiogram/dispatcher/dispatcher.py", line 256, in process_update
    return await self.message_handlers.notify(update.message)
  File "/usr/local/lib/python3.8/dist-packages/aiogram/dispatcher/handler.py", line 116, in notify
    response = await handler_obj.handler(*args, **partial_data)
  File "/home/kirill/spb-beer-bot/tgbot/handlers/start.py", line 61, in take_user_location
    await send_next_three_pubs(message.from_user.id, state)
  File "/home/kirill/spb-beer-bot/tgbot/handlers/start.py", line 83, in send_next_three_pubs
    data['message_pub'][sent_message.message_id] = pub
  File "/usr/local/lib/python3.8/dist-packages/aiogram/dispatcher/storage.py", line 439, in __getitem__
    return self._data[item]
KeyError: 'message_pub'
Cause exception while getting updates.
Traceback (most recent call last):
  File "/usr/local/lib/python3.8/dist-packages/aiohttp/connector.py", line 986, in _wrap_create_connection
    return await self._loop.create_connection(*args, **kwargs)  # type: ignore[return-value]  # noqa
  File "/usr/lib/python3.8/asyncio/base_events.py", line 1025, in create_connection
    raise exceptions[0]
  File "/usr/lib/python3.8/asyncio/base_events.py", line 1010, in create_connection
    sock = await self._connect_sock(
  File "/usr/lib/python3.8/asyncio/base_events.py", line 924, in _connect_sock
    await self.sock_connect(sock, address)
  File "/usr/lib/python3.8/asyncio/selector_events.py", line 496, in sock_connect
    return await fut
  File "/usr/lib/python3.8/asyncio/selector_events.py", line 501, in _sock_connect
    sock.connect(address)
OSError: [Errno 101] Network is unreachable

The above exception was the direct cause of the following exception:

Traceback (most recent call last):
  File "/usr/local/lib/python3.8/dist-packages/aiogram/bot/api.py", line 139, in make_request
    async with session.post(url, data=req, **kwargs) as response:
  File "/usr/local/lib/python3.8/dist-packages/aiohttp/client.py", line 1138, in __aenter__
    self._resp = await self._coro
  File "/usr/local/lib/python3.8/dist-packages/aiohttp/client.py", line 535, in _request
    conn = await self._connector.connect(
  File "/usr/local/lib/python3.8/dist-packages/aiohttp/connector.py", line 542, in connect
    proto = await self._create_connection(req, traces, timeout)
  File "/usr/local/lib/python3.8/dist-packages/aiohttp/connector.py", line 907, in _create_connection
    _, proto = await self._create_direct_connection(req, traces, timeout)
  File "/usr/local/lib/python3.8/dist-packages/aiohttp/connector.py", line 1206, in _create_direct_connection
    raise last_exc
  File "/usr/local/lib/python3.8/dist-packages/aiohttp/connector.py", line 1175, in _create_direct_connection
    transp, proto = await self._wrap_create_connection(
  File "/usr/local/lib/python3.8/dist-packages/aiohttp/connector.py", line 992, in _wrap_create_connection
    raise client_error(req.connection_key, exc) from exc
aiohttp.client_exceptions.ClientConnectorError: Cannot connect to host api.telegram.org:443 ssl:default [Network is unreachable]

During handling of the above exception, another exception occurred:

Traceback (most recent call last):
  File "/usr/local/lib/python3.8/dist-packages/aiogram/dispatcher/dispatcher.py", line 381, in start_polling
    updates = await self.bot.get_updates(
  File "/usr/local/lib/python3.8/dist-packages/aiogram/bot/bot.py", line 110, in get_updates
    result = await self.request(api.Methods.GET_UPDATES, payload)
  File "/usr/local/lib/python3.8/dist-packages/aiogram/bot/base.py", line 231, in request
    return await api.make_request(await self.get_session(), self.server, self.__token, method, data, files,
  File "/usr/local/lib/python3.8/dist-packages/aiogram/bot/api.py", line 142, in make_request
    raise exceptions.NetworkError(f"aiohttp client throws an error: {e.__class__.__name__}: {e}")
aiogram.utils.exceptions.NetworkError: Aiohttp client throws an error: ClientConnectorError: Cannot connect to host api.telegram.org:443 ssl:default [Network is unreachable]
Cause exception while getting updates.
Traceback (most recent call last):
  File "/usr/local/lib/python3.8/dist-packages/aiohttp/connector.py", line 986, in _wrap_create_connection
    return await self._loop.create_connection(*args, **kwargs)  # type: ignore[return-value]  # noqa
  File "/usr/lib/python3.8/asyncio/base_events.py", line 1025, in create_connection
    raise exceptions[0]
  File "/usr/lib/python3.8/asyncio/base_events.py", line 1010, in create_connection
    sock = await self._connect_sock(
  File "/usr/lib/python3.8/asyncio/base_events.py", line 924, in _connect_sock
    await self.sock_connect(sock, address)
  File "/usr/lib/python3.8/asyncio/selector_events.py", line 496, in sock_connect
    return await fut
  File "/usr/lib/python3.8/asyncio/selector_events.py", line 528, in _sock_connect_cb
    raise OSError(err, f'Connect call failed {address}')
ConnectionRefusedError: [Errno 111] Connect call failed ('149.154.167.220', 443)

The above exception was the direct cause of the following exception:

Traceback (most recent call last):
  File "/usr/local/lib/python3.8/dist-packages/aiogram/bot/api.py", line 139, in make_request
    async with session.post(url, data=req, **kwargs) as response:
  File "/usr/local/lib/python3.8/dist-packages/aiohttp/client.py", line 1138, in __aenter__
    self._resp = await self._coro
  File "/usr/local/lib/python3.8/dist-packages/aiohttp/client.py", line 535, in _request
    conn = await self._connector.connect(
  File "/usr/local/lib/python3.8/dist-packages/aiohttp/connector.py", line 542, in connect
    proto = await self._create_connection(req, traces, timeout)
  File "/usr/local/lib/python3.8/dist-packages/aiohttp/connector.py", line 907, in _create_connection
    _, proto = await self._create_direct_connection(req, traces, timeout)
  File "/usr/local/lib/python3.8/dist-packages/aiohttp/connector.py", line 1206, in _create_direct_connection
    raise last_exc
  File "/usr/local/lib/python3.8/dist-packages/aiohttp/connector.py", line 1175, in _create_direct_connection
    transp, proto = await self._wrap_create_connection(
  File "/usr/local/lib/python3.8/dist-packages/aiohttp/connector.py", line 992, in _wrap_create_connection
    raise client_error(req.connection_key, exc) from exc
aiohttp.client_exceptions.ClientConnectorError: Cannot connect to host api.telegram.org:443 ssl:default [Connect call failed ('149.154.167.220', 443)]

During handling of the above exception, another exception occurred:

Traceback (most recent call last):
  File "/usr/local/lib/python3.8/dist-packages/aiogram/dispatcher/dispatcher.py", line 381, in start_polling
    updates = await self.bot.get_updates(
  File "/usr/local/lib/python3.8/dist-packages/aiogram/bot/bot.py", line 110, in get_updates
    result = await self.request(api.Methods.GET_UPDATES, payload)
  File "/usr/local/lib/python3.8/dist-packages/aiogram/bot/base.py", line 231, in request
    return await api.make_request(await self.get_session(), self.server, self.__token, method, data, files,
  File "/usr/local/lib/python3.8/dist-packages/aiogram/bot/api.py", line 142, in make_request
    raise exceptions.NetworkError(f"aiohttp client throws an error: {e.__class__.__name__}: {e}")
aiogram.utils.exceptions.NetworkError: Aiohttp client throws an error: ClientConnectorError: Cannot connect to host api.telegram.org:443 ssl:default [Connect call failed ('149.154.167.220', 443)]
Cause exception while getting updates.
Traceback (most recent call last):
  File "/usr/local/lib/python3.8/dist-packages/aiogram/bot/api.py", line 139, in make_request
    async with session.post(url, data=req, **kwargs) as response:
  File "/usr/local/lib/python3.8/dist-packages/aiohttp/client.py", line 1138, in __aenter__
    self._resp = await self._coro
  File "/usr/local/lib/python3.8/dist-packages/aiohttp/client.py", line 559, in _request
    await resp.start(conn)
  File "/usr/local/lib/python3.8/dist-packages/aiohttp/client_reqrep.py", line 898, in start
    message, payload = await protocol.read()  # type: ignore[union-attr]
  File "/usr/local/lib/python3.8/dist-packages/aiohttp/streams.py", line 616, in read
    await self._waiter
aiohttp.client_exceptions.ServerDisconnectedError: Server disconnected

During handling of the above exception, another exception occurred:

Traceback (most recent call last):
  File "/usr/local/lib/python3.8/dist-packages/aiogram/dispatcher/dispatcher.py", line 381, in start_polling
    updates = await self.bot.get_updates(
  File "/usr/local/lib/python3.8/dist-packages/aiogram/bot/bot.py", line 110, in get_updates
    result = await self.request(api.Methods.GET_UPDATES, payload)
  File "/usr/local/lib/python3.8/dist-packages/aiogram/bot/base.py", line 231, in request
    return await api.make_request(await self.get_session(), self.server, self.__token, method, data, files,
  File "/usr/local/lib/python3.8/dist-packages/aiogram/bot/api.py", line 142, in make_request
    raise exceptions.NetworkError(f"aiohttp client throws an error: {e.__class__.__name__}: {e}")
aiogram.utils.exceptions.NetworkError: Aiohttp client throws an error: ServerDisconnectedError: Server disconnected
Cause exception while getting updates.
Traceback (most recent call last):
  File "/usr/local/lib/python3.8/dist-packages/aiogram/bot/api.py", line 139, in make_request
    async with session.post(url, data=req, **kwargs) as response:
  File "/usr/local/lib/python3.8/dist-packages/aiohttp/client.py", line 1138, in __aenter__
    self._resp = await self._coro
  File "/usr/local/lib/python3.8/dist-packages/aiohttp/client.py", line 559, in _request
    await resp.start(conn)
  File "/usr/local/lib/python3.8/dist-packages/aiohttp/client_reqrep.py", line 898, in start
    message, payload = await protocol.read()  # type: ignore[union-attr]
  File "/usr/local/lib/python3.8/dist-packages/aiohttp/streams.py", line 616, in read
    await self._waiter
aiohttp.client_exceptions.ServerDisconnectedError: Server disconnected

During handling of the above exception, another exception occurred:

Traceback (most recent call last):
  File "/usr/local/lib/python3.8/dist-packages/aiogram/dispatcher/dispatcher.py", line 381, in start_polling
    updates = await self.bot.get_updates(
  File "/usr/local/lib/python3.8/dist-packages/aiogram/bot/bot.py", line 110, in get_updates
    result = await self.request(api.Methods.GET_UPDATES, payload)
  File "/usr/local/lib/python3.8/dist-packages/aiogram/bot/base.py", line 231, in request
    return await api.make_request(await self.get_session(), self.server, self.__token, method, data, files,
  File "/usr/local/lib/python3.8/dist-packages/aiogram/bot/api.py", line 142, in make_request
    raise exceptions.NetworkError(f"aiohttp client throws an error: {e.__class__.__name__}: {e}")
aiogram.utils.exceptions.NetworkError: Aiohttp client throws an error: ServerDisconnectedError: Server disconnected
Cause exception while getting updates.
Traceback (most recent call last):
  File "/usr/local/lib/python3.8/dist-packages/aiogram/bot/api.py", line 139, in make_request
    async with session.post(url, data=req, **kwargs) as response:
  File "/usr/local/lib/python3.8/dist-packages/aiohttp/client.py", line 1138, in __aenter__
    self._resp = await self._coro
  File "/usr/local/lib/python3.8/dist-packages/aiohttp/client.py", line 559, in _request
    await resp.start(conn)
  File "/usr/local/lib/python3.8/dist-packages/aiohttp/client_reqrep.py", line 898, in start
    message, payload = await protocol.read()  # type: ignore[union-attr]
  File "/usr/local/lib/python3.8/dist-packages/aiohttp/streams.py", line 616, in read
    await self._waiter
aiohttp.client_exceptions.ServerDisconnectedError: Server disconnected

During handling of the above exception, another exception occurred:

Traceback (most recent call last):
  File "/usr/local/lib/python3.8/dist-packages/aiogram/dispatcher/dispatcher.py", line 381, in start_polling
    updates = await self.bot.get_updates(
  File "/usr/local/lib/python3.8/dist-packages/aiogram/bot/bot.py", line 110, in get_updates
    result = await self.request(api.Methods.GET_UPDATES, payload)
  File "/usr/local/lib/python3.8/dist-packages/aiogram/bot/base.py", line 231, in request
    return await api.make_request(await self.get_session(), self.server, self.__token, method, data, files,
  File "/usr/local/lib/python3.8/dist-packages/aiogram/bot/api.py", line 142, in make_request
    raise exceptions.NetworkError(f"aiohttp client throws an error: {e.__class__.__name__}: {e}")
aiogram.utils.exceptions.NetworkError: Aiohttp client throws an error: ServerDisconnectedError: Server disconnected
Cause exception while getting updates.
Traceback (most recent call last):
  File "/usr/local/lib/python3.8/dist-packages/aiohttp/connector.py", line 986, in _wrap_create_connection
    return await self._loop.create_connection(*args, **kwargs)  # type: ignore[return-value]  # noqa
  File "/usr/lib/python3.8/asyncio/base_events.py", line 1025, in create_connection
    raise exceptions[0]
  File "/usr/lib/python3.8/asyncio/base_events.py", line 1010, in create_connection
    sock = await self._connect_sock(
  File "/usr/lib/python3.8/asyncio/base_events.py", line 924, in _connect_sock
    await self.sock_connect(sock, address)
  File "/usr/lib/python3.8/asyncio/selector_events.py", line 496, in sock_connect
    return await fut
  File "/usr/lib/python3.8/asyncio/selector_events.py", line 501, in _sock_connect
    sock.connect(address)
OSError: [Errno 101] Network is unreachable

The above exception was the direct cause of the following exception:

Traceback (most recent call last):
  File "/usr/local/lib/python3.8/dist-packages/aiogram/bot/api.py", line 139, in make_request
    async with session.post(url, data=req, **kwargs) as response:
  File "/usr/local/lib/python3.8/dist-packages/aiohttp/client.py", line 1138, in __aenter__
    self._resp = await self._coro
  File "/usr/local/lib/python3.8/dist-packages/aiohttp/client.py", line 535, in _request
    conn = await self._connector.connect(
  File "/usr/local/lib/python3.8/dist-packages/aiohttp/connector.py", line 542, in connect
    proto = await self._create_connection(req, traces, timeout)
  File "/usr/local/lib/python3.8/dist-packages/aiohttp/connector.py", line 907, in _create_connection
    _, proto = await self._create_direct_connection(req, traces, timeout)
  File "/usr/local/lib/python3.8/dist-packages/aiohttp/connector.py", line 1206, in _create_direct_connection
    raise last_exc
  File "/usr/local/lib/python3.8/dist-packages/aiohttp/connector.py", line 1175, in _create_direct_connection
    transp, proto = await self._wrap_create_connection(
  File "/usr/local/lib/python3.8/dist-packages/aiohttp/connector.py", line 992, in _wrap_create_connection
    raise client_error(req.connection_key, exc) from exc
aiohttp.client_exceptions.ClientConnectorError: Cannot connect to host api.telegram.org:443 ssl:default [Network is unreachable]

During handling of the above exception, another exception occurred:

Traceback (most recent call last):
  File "/usr/local/lib/python3.8/dist-packages/aiogram/dispatcher/dispatcher.py", line 381, in start_polling
    updates = await self.bot.get_updates(
  File "/usr/local/lib/python3.8/dist-packages/aiogram/bot/bot.py", line 110, in get_updates
    result = await self.request(api.Methods.GET_UPDATES, payload)
  File "/usr/local/lib/python3.8/dist-packages/aiogram/bot/base.py", line 231, in request
    return await api.make_request(await self.get_session(), self.server, self.__token, method, data, files,
  File "/usr/local/lib/python3.8/dist-packages/aiogram/bot/api.py", line 142, in make_request
    raise exceptions.NetworkError(f"aiohttp client throws an error: {e.__class__.__name__}: {e}")
aiogram.utils.exceptions.NetworkError: Aiohttp client throws an error: ClientConnectorError: Cannot connect to host api.telegram.org:443 ssl:default [Network is unreachable]
Cause exception while getting updates.
Traceback (most recent call last):
  File "/usr/local/lib/python3.8/dist-packages/aiogram/bot/api.py", line 139, in make_request
    async with session.post(url, data=req, **kwargs) as response:
  File "/usr/local/lib/python3.8/dist-packages/aiohttp/client.py", line 1138, in __aenter__
    self._resp = await self._coro
  File "/usr/local/lib/python3.8/dist-packages/aiohttp/client.py", line 559, in _request
    await resp.start(conn)
  File "/usr/local/lib/python3.8/dist-packages/aiohttp/client_reqrep.py", line 898, in start
    message, payload = await protocol.read()  # type: ignore[union-attr]
  File "/usr/local/lib/python3.8/dist-packages/aiohttp/streams.py", line 616, in read
    await self._waiter
aiohttp.client_exceptions.ServerDisconnectedError: Server disconnected

During handling of the above exception, another exception occurred:

Traceback (most recent call last):
  File "/usr/local/lib/python3.8/dist-packages/aiogram/dispatcher/dispatcher.py", line 381, in start_polling
    updates = await self.bot.get_updates(
  File "/usr/local/lib/python3.8/dist-packages/aiogram/bot/bot.py", line 110, in get_updates
    result = await self.request(api.Methods.GET_UPDATES, payload)
  File "/usr/local/lib/python3.8/dist-packages/aiogram/bot/base.py", line 231, in request
    return await api.make_request(await self.get_session(), self.server, self.__token, method, data, files,
  File "/usr/local/lib/python3.8/dist-packages/aiogram/bot/api.py", line 142, in make_request
    raise exceptions.NetworkError(f"aiohttp client throws an error: {e.__class__.__name__}: {e}")
aiogram.utils.exceptions.NetworkError: Aiohttp client throws an error: ServerDisconnectedError: Server disconnected
Cause exception while getting updates.
Traceback (most recent call last):
  File "/usr/local/lib/python3.8/dist-packages/aiohttp/connector.py", line 986, in _wrap_create_connection
    return await self._loop.create_connection(*args, **kwargs)  # type: ignore[return-value]  # noqa
  File "/usr/lib/python3.8/asyncio/base_events.py", line 1025, in create_connection
    raise exceptions[0]
  File "/usr/lib/python3.8/asyncio/base_events.py", line 1010, in create_connection
    sock = await self._connect_sock(
  File "/usr/lib/python3.8/asyncio/base_events.py", line 924, in _connect_sock
    await self.sock_connect(sock, address)
  File "/usr/lib/python3.8/asyncio/selector_events.py", line 496, in sock_connect
    return await fut
  File "/usr/lib/python3.8/asyncio/selector_events.py", line 501, in _sock_connect
    sock.connect(address)
OSError: [Errno 101] Network is unreachable

The above exception was the direct cause of the following exception:

Traceback (most recent call last):
  File "/usr/local/lib/python3.8/dist-packages/aiogram/bot/api.py", line 139, in make_request
    async with session.post(url, data=req, **kwargs) as response:
  File "/usr/local/lib/python3.8/dist-packages/aiohttp/client.py", line 1138, in __aenter__
    self._resp = await self._coro
  File "/usr/local/lib/python3.8/dist-packages/aiohttp/client.py", line 535, in _request
    conn = await self._connector.connect(
  File "/usr/local/lib/python3.8/dist-packages/aiohttp/connector.py", line 542, in connect
    proto = await self._create_connection(req, traces, timeout)
  File "/usr/local/lib/python3.8/dist-packages/aiohttp/connector.py", line 907, in _create_connection
    _, proto = await self._create_direct_connection(req, traces, timeout)
  File "/usr/local/lib/python3.8/dist-packages/aiohttp/connector.py", line 1206, in _create_direct_connection
    raise last_exc
  File "/usr/local/lib/python3.8/dist-packages/aiohttp/connector.py", line 1175, in _create_direct_connection
    transp, proto = await self._wrap_create_connection(
  File "/usr/local/lib/python3.8/dist-packages/aiohttp/connector.py", line 992, in _wrap_create_connection
    raise client_error(req.connection_key, exc) from exc
aiohttp.client_exceptions.ClientConnectorError: Cannot connect to host api.telegram.org:443 ssl:default [Network is unreachable]

During handling of the above exception, another exception occurred:

Traceback (most recent call last):
  File "/usr/local/lib/python3.8/dist-packages/aiogram/dispatcher/dispatcher.py", line 381, in start_polling
    updates = await self.bot.get_updates(
  File "/usr/local/lib/python3.8/dist-packages/aiogram/bot/bot.py", line 110, in get_updates
    result = await self.request(api.Methods.GET_UPDATES, payload)
  File "/usr/local/lib/python3.8/dist-packages/aiogram/bot/base.py", line 231, in request
    return await api.make_request(await self.get_session(), self.server, self.__token, method, data, files,
  File "/usr/local/lib/python3.8/dist-packages/aiogram/bot/api.py", line 142, in make_request
    raise exceptions.NetworkError(f"aiohttp client throws an error: {e.__class__.__name__}: {e}")
aiogram.utils.exceptions.NetworkError: Aiohttp client throws an error: ClientConnectorError: Cannot connect to host api.telegram.org:443 ssl:default [Network is unreachable]
Cause exception while getting updates.
Traceback (most recent call last):
  File "/usr/local/lib/python3.8/dist-packages/aiohttp/connector.py", line 986, in _wrap_create_connection
    return await self._loop.create_connection(*args, **kwargs)  # type: ignore[return-value]  # noqa
  File "/usr/lib/python3.8/asyncio/base_events.py", line 1025, in create_connection
    raise exceptions[0]
  File "/usr/lib/python3.8/asyncio/base_events.py", line 1010, in create_connection
    sock = await self._connect_sock(
  File "/usr/lib/python3.8/asyncio/base_events.py", line 924, in _connect_sock
    await self.sock_connect(sock, address)
  File "/usr/lib/python3.8/asyncio/selector_events.py", line 496, in sock_connect
    return await fut
  File "/usr/lib/python3.8/asyncio/selector_events.py", line 528, in _sock_connect_cb
    raise OSError(err, f'Connect call failed {address}')
ConnectionRefusedError: [Errno 111] Connect call failed ('149.154.167.220', 443)

The above exception was the direct cause of the following exception:

Traceback (most recent call last):
  File "/usr/local/lib/python3.8/dist-packages/aiogram/bot/api.py", line 139, in make_request
    async with session.post(url, data=req, **kwargs) as response:
  File "/usr/local/lib/python3.8/dist-packages/aiohttp/client.py", line 1138, in __aenter__
    self._resp = await self._coro
  File "/usr/local/lib/python3.8/dist-packages/aiohttp/client.py", line 535, in _request
    conn = await self._connector.connect(
  File "/usr/local/lib/python3.8/dist-packages/aiohttp/connector.py", line 542, in connect
    proto = await self._create_connection(req, traces, timeout)
  File "/usr/local/lib/python3.8/dist-packages/aiohttp/connector.py", line 907, in _create_connection
    _, proto = await self._create_direct_connection(req, traces, timeout)
  File "/usr/local/lib/python3.8/dist-packages/aiohttp/connector.py", line 1206, in _create_direct_connection
    raise last_exc
  File "/usr/local/lib/python3.8/dist-packages/aiohttp/connector.py", line 1175, in _create_direct_connection
    transp, proto = await self._wrap_create_connection(
  File "/usr/local/lib/python3.8/dist-packages/aiohttp/connector.py", line 992, in _wrap_create_connection
    raise client_error(req.connection_key, exc) from exc
aiohttp.client_exceptions.ClientConnectorError: Cannot connect to host api.telegram.org:443 ssl:default [Connect call failed ('149.154.167.220', 443)]

During handling of the above exception, another exception occurred:

Traceback (most recent call last):
  File "/usr/local/lib/python3.8/dist-packages/aiogram/dispatcher/dispatcher.py", line 381, in start_polling
    updates = await self.bot.get_updates(
  File "/usr/local/lib/python3.8/dist-packages/aiogram/bot/bot.py", line 110, in get_updates
    result = await self.request(api.Methods.GET_UPDATES, payload)
  File "/usr/local/lib/python3.8/dist-packages/aiogram/bot/base.py", line 231, in request
    return await api.make_request(await self.get_session(), self.server, self.__token, method, data, files,
  File "/usr/local/lib/python3.8/dist-packages/aiogram/bot/api.py", line 142, in make_request
    raise exceptions.NetworkError(f"aiohttp client throws an error: {e.__class__.__name__}: {e}")
aiogram.utils.exceptions.NetworkError: Aiohttp client throws an error: ClientConnectorError: Cannot connect to host api.telegram.org:443 ssl:default [Connect call failed ('149.154.167.220', 443)]
Cause exception while getting updates.
Traceback (most recent call last):
  File "/usr/local/lib/python3.8/dist-packages/aiohttp/connector.py", line 986, in _wrap_create_connection
    return await self._loop.create_connection(*args, **kwargs)  # type: ignore[return-value]  # noqa
  File "/usr/lib/python3.8/asyncio/base_events.py", line 1025, in create_connection
    raise exceptions[0]
  File "/usr/lib/python3.8/asyncio/base_events.py", line 1010, in create_connection
    sock = await self._connect_sock(
  File "/usr/lib/python3.8/asyncio/base_events.py", line 924, in _connect_sock
    await self.sock_connect(sock, address)
  File "/usr/lib/python3.8/asyncio/selector_events.py", line 496, in sock_connect
    return await fut
  File "/usr/lib/python3.8/asyncio/selector_events.py", line 501, in _sock_connect
    sock.connect(address)
OSError: [Errno 101] Network is unreachable

The above exception was the direct cause of the following exception:

Traceback (most recent call last):
  File "/usr/local/lib/python3.8/dist-packages/aiogram/bot/api.py", line 139, in make_request
    async with session.post(url, data=req, **kwargs) as response:
  File "/usr/local/lib/python3.8/dist-packages/aiohttp/client.py", line 1138, in __aenter__
    self._resp = await self._coro
  File "/usr/local/lib/python3.8/dist-packages/aiohttp/client.py", line 535, in _request
    conn = await self._connector.connect(
  File "/usr/local/lib/python3.8/dist-packages/aiohttp/connector.py", line 542, in connect
    proto = await self._create_connection(req, traces, timeout)
  File "/usr/local/lib/python3.8/dist-packages/aiohttp/connector.py", line 907, in _create_connection
    _, proto = await self._create_direct_connection(req, traces, timeout)
  File "/usr/local/lib/python3.8/dist-packages/aiohttp/connector.py", line 1206, in _create_direct_connection
    raise last_exc
  File "/usr/local/lib/python3.8/dist-packages/aiohttp/connector.py", line 1175, in _create_direct_connection
    transp, proto = await self._wrap_create_connection(
  File "/usr/local/lib/python3.8/dist-packages/aiohttp/connector.py", line 992, in _wrap_create_connection
    raise client_error(req.connection_key, exc) from exc
aiohttp.client_exceptions.ClientConnectorError: Cannot connect to host api.telegram.org:443 ssl:default [Network is unreachable]

During handling of the above exception, another exception occurred:

Traceback (most recent call last):
  File "/usr/local/lib/python3.8/dist-packages/aiogram/dispatcher/dispatcher.py", line 381, in start_polling
    updates = await self.bot.get_updates(
  File "/usr/local/lib/python3.8/dist-packages/aiogram/bot/bot.py", line 110, in get_updates
    result = await self.request(api.Methods.GET_UPDATES, payload)
  File "/usr/local/lib/python3.8/dist-packages/aiogram/bot/base.py", line 231, in request
    return await api.make_request(await self.get_session(), self.server, self.__token, method, data, files,
  File "/usr/local/lib/python3.8/dist-packages/aiogram/bot/api.py", line 142, in make_request
    raise exceptions.NetworkError(f"aiohttp client throws an error: {e.__class__.__name__}: {e}")
aiogram.utils.exceptions.NetworkError: Aiohttp client throws an error: ClientConnectorError: Cannot connect to host api.telegram.org:443 ssl:default [Network is unreachable]
Cause exception while getting updates.
Traceback (most recent call last):
  File "/usr/local/lib/python3.8/dist-packages/aiohttp/connector.py", line 986, in _wrap_create_connection
    return await self._loop.create_connection(*args, **kwargs)  # type: ignore[return-value]  # noqa
  File "/usr/lib/python3.8/asyncio/base_events.py", line 1025, in create_connection
    raise exceptions[0]
  File "/usr/lib/python3.8/asyncio/base_events.py", line 1010, in create_connection
    sock = await self._connect_sock(
  File "/usr/lib/python3.8/asyncio/base_events.py", line 924, in _connect_sock
    await self.sock_connect(sock, address)
  File "/usr/lib/python3.8/asyncio/selector_events.py", line 496, in sock_connect
    return await fut
  File "/usr/lib/python3.8/asyncio/selector_events.py", line 528, in _sock_connect_cb
    raise OSError(err, f'Connect call failed {address}')
ConnectionRefusedError: [Errno 111] Connect call failed ('149.154.167.220', 443)

The above exception was the direct cause of the following exception:

Traceback (most recent call last):
  File "/usr/local/lib/python3.8/dist-packages/aiogram/bot/api.py", line 139, in make_request
    async with session.post(url, data=req, **kwargs) as response:
  File "/usr/local/lib/python3.8/dist-packages/aiohttp/client.py", line 1138, in __aenter__
    self._resp = await self._coro
  File "/usr/local/lib/python3.8/dist-packages/aiohttp/client.py", line 535, in _request
    conn = await self._connector.connect(
  File "/usr/local/lib/python3.8/dist-packages/aiohttp/connector.py", line 542, in connect
    proto = await self._create_connection(req, traces, timeout)
  File "/usr/local/lib/python3.8/dist-packages/aiohttp/connector.py", line 907, in _create_connection
    _, proto = await self._create_direct_connection(req, traces, timeout)
  File "/usr/local/lib/python3.8/dist-packages/aiohttp/connector.py", line 1206, in _create_direct_connection
    raise last_exc
  File "/usr/local/lib/python3.8/dist-packages/aiohttp/connector.py", line 1175, in _create_direct_connection
    transp, proto = await self._wrap_create_connection(
  File "/usr/local/lib/python3.8/dist-packages/aiohttp/connector.py", line 992, in _wrap_create_connection
    raise client_error(req.connection_key, exc) from exc
aiohttp.client_exceptions.ClientConnectorError: Cannot connect to host api.telegram.org:443 ssl:default [Connect call failed ('149.154.167.220', 443)]

During handling of the above exception, another exception occurred:

Traceback (most recent call last):
  File "/usr/local/lib/python3.8/dist-packages/aiogram/dispatcher/dispatcher.py", line 381, in start_polling
    updates = await self.bot.get_updates(
  File "/usr/local/lib/python3.8/dist-packages/aiogram/bot/bot.py", line 110, in get_updates
    result = await self.request(api.Methods.GET_UPDATES, payload)
  File "/usr/local/lib/python3.8/dist-packages/aiogram/bot/base.py", line 231, in request
    return await api.make_request(await self.get_session(), self.server, self.__token, method, data, files,
  File "/usr/local/lib/python3.8/dist-packages/aiogram/bot/api.py", line 142, in make_request
    raise exceptions.NetworkError(f"aiohttp client throws an error: {e.__class__.__name__}: {e}")
aiogram.utils.exceptions.NetworkError: Aiohttp client throws an error: ClientConnectorError: Cannot connect to host api.telegram.org:443 ssl:default [Connect call failed ('149.154.167.220', 443)]
Cause exception while getting updates.
Traceback (most recent call last):
  File "/usr/local/lib/python3.8/dist-packages/aiohttp/connector.py", line 986, in _wrap_create_connection
    return await self._loop.create_connection(*args, **kwargs)  # type: ignore[return-value]  # noqa
  File "/usr/lib/python3.8/asyncio/base_events.py", line 1025, in create_connection
    raise exceptions[0]
  File "/usr/lib/python3.8/asyncio/base_events.py", line 1010, in create_connection
    sock = await self._connect_sock(
  File "/usr/lib/python3.8/asyncio/base_events.py", line 924, in _connect_sock
    await self.sock_connect(sock, address)
  File "/usr/lib/python3.8/asyncio/selector_events.py", line 496, in sock_connect
    return await fut
  File "/usr/lib/python3.8/asyncio/selector_events.py", line 501, in _sock_connect
    sock.connect(address)
OSError: [Errno 101] Network is unreachable

The above exception was the direct cause of the following exception:

Traceback (most recent call last):
  File "/usr/local/lib/python3.8/dist-packages/aiogram/bot/api.py", line 139, in make_request
    async with session.post(url, data=req, **kwargs) as response:
  File "/usr/local/lib/python3.8/dist-packages/aiohttp/client.py", line 1138, in __aenter__
    self._resp = await self._coro
  File "/usr/local/lib/python3.8/dist-packages/aiohttp/client.py", line 535, in _request
    conn = await self._connector.connect(
  File "/usr/local/lib/python3.8/dist-packages/aiohttp/connector.py", line 542, in connect
    proto = await self._create_connection(req, traces, timeout)
  File "/usr/local/lib/python3.8/dist-packages/aiohttp/connector.py", line 907, in _create_connection
    _, proto = await self._create_direct_connection(req, traces, timeout)
  File "/usr/local/lib/python3.8/dist-packages/aiohttp/connector.py", line 1206, in _create_direct_connection
    raise last_exc
  File "/usr/local/lib/python3.8/dist-packages/aiohttp/connector.py", line 1175, in _create_direct_connection
    transp, proto = await self._wrap_create_connection(
  File "/usr/local/lib/python3.8/dist-packages/aiohttp/connector.py", line 992, in _wrap_create_connection
    raise client_error(req.connection_key, exc) from exc
aiohttp.client_exceptions.ClientConnectorError: Cannot connect to host api.telegram.org:443 ssl:default [Network is unreachable]

During handling of the above exception, another exception occurred:

Traceback (most recent call last):
  File "/usr/local/lib/python3.8/dist-packages/aiogram/dispatcher/dispatcher.py", line 381, in start_polling
    updates = await self.bot.get_updates(
  File "/usr/local/lib/python3.8/dist-packages/aiogram/bot/bot.py", line 110, in get_updates
    result = await self.request(api.Methods.GET_UPDATES, payload)
  File "/usr/local/lib/python3.8/dist-packages/aiogram/bot/base.py", line 231, in request
    return await api.make_request(await self.get_session(), self.server, self.__token, method, data, files,
  File "/usr/local/lib/python3.8/dist-packages/aiogram/bot/api.py", line 142, in make_request
    raise exceptions.NetworkError(f"aiohttp client throws an error: {e.__class__.__name__}: {e}")
aiogram.utils.exceptions.NetworkError: Aiohttp client throws an error: ClientConnectorError: Cannot connect to host api.telegram.org:443 ssl:default [Network is unreachable]
Cause exception while getting updates.
Traceback (most recent call last):
  File "/usr/local/lib/python3.8/dist-packages/aiogram/bot/api.py", line 139, in make_request
    async with session.post(url, data=req, **kwargs) as response:
  File "/usr/local/lib/python3.8/dist-packages/aiohttp/client.py", line 1138, in __aenter__
    self._resp = await self._coro
  File "/usr/local/lib/python3.8/dist-packages/aiohttp/client.py", line 559, in _request
    await resp.start(conn)
  File "/usr/local/lib/python3.8/dist-packages/aiohttp/client_reqrep.py", line 898, in start
    message, payload = await protocol.read()  # type: ignore[union-attr]
  File "/usr/local/lib/python3.8/dist-packages/aiohttp/streams.py", line 616, in read
    await self._waiter
aiohttp.client_exceptions.ServerDisconnectedError: Server disconnected

During handling of the above exception, another exception occurred:

Traceback (most recent call last):
  File "/usr/local/lib/python3.8/dist-packages/aiogram/dispatcher/dispatcher.py", line 381, in start_polling
    updates = await self.bot.get_updates(
  File "/usr/local/lib/python3.8/dist-packages/aiogram/bot/bot.py", line 110, in get_updates
    result = await self.request(api.Methods.GET_UPDATES, payload)
  File "/usr/local/lib/python3.8/dist-packages/aiogram/bot/base.py", line 231, in request
    return await api.make_request(await self.get_session(), self.server, self.__token, method, data, files,
  File "/usr/local/lib/python3.8/dist-packages/aiogram/bot/api.py", line 142, in make_request
    raise exceptions.NetworkError(f"aiohttp client throws an error: {e.__class__.__name__}: {e}")
aiogram.utils.exceptions.NetworkError: Aiohttp client throws an error: ServerDisconnectedError: Server disconnected
Traceback (most recent call last):
  File "app.py", line 2, in <module>
    from loader import dp
  File "/home/kirill/spb-beer-bot/loader.py", line 10, in <module>
    db = Database()
  File "/home/kirill/spb-beer-bot/tgbot/database.py", line 10, in __init__
    self.pool = loop.run_until_complete(
  File "/usr/lib/python3.8/asyncio/base_events.py", line 616, in run_until_complete
    return future.result()
  File "/usr/lib/python3.8/asyncio/tasks.py", line 695, in _wrap_awaitable
    return (yield from awaitable.__await__())
  File "/usr/local/lib/python3.8/dist-packages/asyncpg/pool.py", line 413, in _async__init__
    await self._initialize()
  File "/usr/local/lib/python3.8/dist-packages/asyncpg/pool.py", line 441, in _initialize
    await first_ch.connect()
  File "/usr/local/lib/python3.8/dist-packages/asyncpg/pool.py", line 133, in connect
    self._con = await self._pool._get_new_connection()
  File "/usr/local/lib/python3.8/dist-packages/asyncpg/pool.py", line 511, in _get_new_connection
    con = await connection.connect(
  File "/usr/local/lib/python3.8/dist-packages/asyncpg/connection.py", line 2093, in connect
    return await connect_utils._connect(
  File "/usr/local/lib/python3.8/dist-packages/asyncpg/connect_utils.py", line 903, in _connect
    raise last_error
  File "/usr/local/lib/python3.8/dist-packages/asyncpg/connect_utils.py", line 889, in _connect
    return await _connect_addr(
  File "/usr/local/lib/python3.8/dist-packages/asyncpg/connect_utils.py", line 781, in _connect_addr
    return await __connect_addr(params, timeout, True, *args)
  File "/usr/local/lib/python3.8/dist-packages/asyncpg/connect_utils.py", line 833, in __connect_addr
    tr, pr = await compat.wait_for(connector, timeout=timeout)
  File "/usr/local/lib/python3.8/dist-packages/asyncpg/compat.py", line 66, in wait_for
    return await asyncio.wait_for(fut, timeout)
  File "/usr/lib/python3.8/asyncio/tasks.py", line 494, in wait_for
    return fut.result()
  File "/usr/local/lib/python3.8/dist-packages/asyncpg/connect_utils.py", line 692, in _create_ssl_connection
    tr, pr = await loop.create_connection(
  File "/usr/lib/python3.8/asyncio/base_events.py", line 1025, in create_connection
    raise exceptions[0]
  File "/usr/lib/python3.8/asyncio/base_events.py", line 1010, in create_connection
    sock = await self._connect_sock(
  File "/usr/lib/python3.8/asyncio/base_events.py", line 924, in _connect_sock
    await self.sock_connect(sock, address)
  File "/usr/lib/python3.8/asyncio/selector_events.py", line 496, in sock_connect
    return await fut
  File "/usr/lib/python3.8/asyncio/selector_events.py", line 528, in _sock_connect_cb
    raise OSError(err, f'Connect call failed {address}')
OSError: [Errno 113] Connect call failed ('194.87.79.86', 5431)
Cause exception while getting updates.
Traceback (most recent call last):
  File "/usr/local/lib/python3.8/dist-packages/aiogram/dispatcher/dispatcher.py", line 381, in start_polling
    updates = await self.bot.get_updates(
  File "/usr/local/lib/python3.8/dist-packages/aiogram/bot/bot.py", line 110, in get_updates
    result = await self.request(api.Methods.GET_UPDATES, payload)
  File "/usr/local/lib/python3.8/dist-packages/aiogram/bot/base.py", line 231, in request
    return await api.make_request(await self.get_session(), self.server, self.__token, method, data, files,
  File "/usr/local/lib/python3.8/dist-packages/aiogram/bot/api.py", line 140, in make_request
    return check_result(method, response.content_type, response.status, await response.text())
  File "/usr/local/lib/python3.8/dist-packages/aiogram/bot/api.py", line 128, in check_result
    raise exceptions.TelegramAPIError(description)
aiogram.utils.exceptions.TelegramAPIError: Bad Gateway
Cause exception while getting updates.
Traceback (most recent call last):
  File "/usr/local/lib/python3.8/dist-packages/aiogram/dispatcher/dispatcher.py", line 381, in start_polling
    updates = await self.bot.get_updates(
  File "/usr/local/lib/python3.8/dist-packages/aiogram/bot/bot.py", line 110, in get_updates
    result = await self.request(api.Methods.GET_UPDATES, payload)
  File "/usr/local/lib/python3.8/dist-packages/aiogram/bot/base.py", line 231, in request
    return await api.make_request(await self.get_session(), self.server, self.__token, method, data, files,
  File "/usr/local/lib/python3.8/dist-packages/aiogram/bot/api.py", line 140, in make_request
    return check_result(method, response.content_type, response.status, await response.text())
  File "/usr/local/lib/python3.8/dist-packages/aiogram/bot/api.py", line 128, in check_result
    raise exceptions.TelegramAPIError(description)
aiogram.utils.exceptions.TelegramAPIError: Bad Gateway
Cause exception while getting updates.
Traceback (most recent call last):
  File "/usr/local/lib/python3.8/dist-packages/aiogram/dispatcher/dispatcher.py", line 381, in start_polling
    updates = await self.bot.get_updates(
  File "/usr/local/lib/python3.8/dist-packages/aiogram/bot/bot.py", line 110, in get_updates
    result = await self.request(api.Methods.GET_UPDATES, payload)
  File "/usr/local/lib/python3.8/dist-packages/aiogram/bot/base.py", line 231, in request
    return await api.make_request(await self.get_session(), self.server, self.__token, method, data, files,
  File "/usr/local/lib/python3.8/dist-packages/aiogram/bot/api.py", line 140, in make_request
    return check_result(method, response.content_type, response.status, await response.text())
  File "/usr/local/lib/python3.8/dist-packages/aiogram/bot/api.py", line 128, in check_result
    raise exceptions.TelegramAPIError(description)
aiogram.utils.exceptions.TelegramAPIError: Bad Gateway
Cause exception while getting updates.
Traceback (most recent call last):
  File "/usr/local/lib/python3.8/dist-packages/aiogram/dispatcher/dispatcher.py", line 381, in start_polling
    updates = await self.bot.get_updates(
  File "/usr/local/lib/python3.8/dist-packages/aiogram/bot/bot.py", line 110, in get_updates
    result = await self.request(api.Methods.GET_UPDATES, payload)
  File "/usr/local/lib/python3.8/dist-packages/aiogram/bot/base.py", line 231, in request
    return await api.make_request(await self.get_session(), self.server, self.__token, method, data, files,
  File "/usr/local/lib/python3.8/dist-packages/aiogram/bot/api.py", line 140, in make_request
    return check_result(method, response.content_type, response.status, await response.text())
  File "/usr/local/lib/python3.8/dist-packages/aiogram/bot/api.py", line 128, in check_result
    raise exceptions.TelegramAPIError(description)
aiogram.utils.exceptions.TelegramAPIError: Bad Gateway
Task exception was never retrieved
future: <Task finished name='Task-38230' coro=<Dispatcher._process_polling_updates() done, defined at /usr/local/lib/python3.8/dist-packages/aiogram/dispatcher/dispatcher.py:407> exception=KeyError('message_pub')>
Traceback (most recent call last):
  File "/usr/local/lib/python3.8/dist-packages/aiogram/dispatcher/dispatcher.py", line 415, in _process_polling_updates
    for responses in itertools.chain.from_iterable(await self.process_updates(updates, fast)):
  File "/usr/local/lib/python3.8/dist-packages/aiogram/dispatcher/dispatcher.py", line 235, in process_updates
    return await asyncio.gather(*tasks)
  File "/usr/local/lib/python3.8/dist-packages/aiogram/dispatcher/handler.py", line 116, in notify
    response = await handler_obj.handler(*args, **partial_data)
  File "/usr/local/lib/python3.8/dist-packages/aiogram/dispatcher/dispatcher.py", line 256, in process_update
    return await self.message_handlers.notify(update.message)
  File "/usr/local/lib/python3.8/dist-packages/aiogram/dispatcher/handler.py", line 116, in notify
    response = await handler_obj.handler(*args, **partial_data)
  File "/home/kirill/spb-beer-bot/tgbot/handlers/start.py", line 61, in take_user_location
    await send_next_three_pubs(message.from_user.id, state)
  File "/home/kirill/spb-beer-bot/tgbot/handlers/start.py", line 83, in send_next_three_pubs
    data['message_pub'][sent_message.message_id] = pub
  File "/usr/local/lib/python3.8/dist-packages/aiogram/dispatcher/storage.py", line 439, in __getitem__
    return self._data[item]
KeyError: 'message_pub'
Cause exception while getting updates.
Traceback (most recent call last):
  File "/usr/local/lib/python3.8/dist-packages/aiogram/dispatcher/dispatcher.py", line 381, in start_polling
    updates = await self.bot.get_updates(
  File "/usr/local/lib/python3.8/dist-packages/aiogram/bot/bot.py", line 110, in get_updates
    result = await self.request(api.Methods.GET_UPDATES, payload)
  File "/usr/local/lib/python3.8/dist-packages/aiogram/bot/base.py", line 231, in request
    return await api.make_request(await self.get_session(), self.server, self.__token, method, data, files,
  File "/usr/local/lib/python3.8/dist-packages/aiogram/bot/api.py", line 140, in make_request
    return check_result(method, response.content_type, response.status, await response.text())
  File "/usr/local/lib/python3.8/dist-packages/aiogram/bot/api.py", line 128, in check_result
    raise exceptions.TelegramAPIError(description)
aiogram.utils.exceptions.TelegramAPIError: Bad Gateway
Cause exception while getting updates.
Traceback (most recent call last):
  File "/usr/local/lib/python3.8/dist-packages/aiogram/dispatcher/dispatcher.py", line 381, in start_polling
    updates = await self.bot.get_updates(
  File "/usr/local/lib/python3.8/dist-packages/aiogram/bot/bot.py", line 110, in get_updates
    result = await self.request(api.Methods.GET_UPDATES, payload)
  File "/usr/local/lib/python3.8/dist-packages/aiogram/bot/base.py", line 231, in request
    return await api.make_request(await self.get_session(), self.server, self.__token, method, data, files,
  File "/usr/local/lib/python3.8/dist-packages/aiogram/bot/api.py", line 140, in make_request
    return check_result(method, response.content_type, response.status, await response.text())
  File "/usr/local/lib/python3.8/dist-packages/aiogram/bot/api.py", line 128, in check_result
    raise exceptions.TelegramAPIError(description)
aiogram.utils.exceptions.TelegramAPIError: Bad Gateway
Task exception was never retrieved
future: <Task finished name='Task-66592' coro=<Dispatcher._process_polling_updates() done, defined at /usr/local/lib/python3.8/dist-packages/aiogram/dispatcher/dispatcher.py:407> exception=KeyError('message_pub')>
Traceback (most recent call last):
  File "/usr/local/lib/python3.8/dist-packages/aiogram/dispatcher/dispatcher.py", line 415, in _process_polling_updates
    for responses in itertools.chain.from_iterable(await self.process_updates(updates, fast)):
  File "/usr/local/lib/python3.8/dist-packages/aiogram/dispatcher/dispatcher.py", line 235, in process_updates
    return await asyncio.gather(*tasks)
  File "/usr/local/lib/python3.8/dist-packages/aiogram/dispatcher/handler.py", line 116, in notify
    response = await handler_obj.handler(*args, **partial_data)
  File "/usr/local/lib/python3.8/dist-packages/aiogram/dispatcher/dispatcher.py", line 256, in process_update
    return await self.message_handlers.notify(update.message)
  File "/usr/local/lib/python3.8/dist-packages/aiogram/dispatcher/handler.py", line 116, in notify
    response = await handler_obj.handler(*args, **partial_data)
  File "/home/kirill/spb-beer-bot/tgbot/handlers/start.py", line 61, in take_user_location
    await send_next_three_pubs(message.from_user.id, state)
  File "/home/kirill/spb-beer-bot/tgbot/handlers/start.py", line 83, in send_next_three_pubs
    data['message_pub'][sent_message.message_id] = pub
  File "/usr/local/lib/python3.8/dist-packages/aiogram/dispatcher/storage.py", line 439, in __getitem__
    return self._data[item]
KeyError: 'message_pub'
Task exception was never retrieved
future: <Task finished name='Task-66609' coro=<Dispatcher._process_polling_updates() done, defined at /usr/local/lib/python3.8/dist-packages/aiogram/dispatcher/dispatcher.py:407> exception=KeyError('message_pub')>
Traceback (most recent call last):
  File "/usr/local/lib/python3.8/dist-packages/aiogram/dispatcher/dispatcher.py", line 415, in _process_polling_updates
    for responses in itertools.chain.from_iterable(await self.process_updates(updates, fast)):
  File "/usr/local/lib/python3.8/dist-packages/aiogram/dispatcher/dispatcher.py", line 235, in process_updates
    return await asyncio.gather(*tasks)
  File "/usr/local/lib/python3.8/dist-packages/aiogram/dispatcher/handler.py", line 116, in notify
    response = await handler_obj.handler(*args, **partial_data)
  File "/usr/local/lib/python3.8/dist-packages/aiogram/dispatcher/dispatcher.py", line 256, in process_update
    return await self.message_handlers.notify(update.message)
  File "/usr/local/lib/python3.8/dist-packages/aiogram/dispatcher/handler.py", line 116, in notify
    response = await handler_obj.handler(*args, **partial_data)
  File "/home/kirill/spb-beer-bot/tgbot/handlers/start.py", line 61, in take_user_location
    await send_next_three_pubs(message.from_user.id, state)
  File "/home/kirill/spb-beer-bot/tgbot/handlers/start.py", line 83, in send_next_three_pubs
    data['message_pub'][sent_message.message_id] = pub
  File "/usr/local/lib/python3.8/dist-packages/aiogram/dispatcher/storage.py", line 439, in __getitem__
    return self._data[item]
KeyError: 'message_pub'
